File: 05-17-2018_Cr2ALC.ras
*RAS_DATA_START
*RAS_HEADER_START
*DISP_FMT_X "%.3f"
*DISP_FMT_Y "%.0f"
*DISP_FULLSCALE "590.4000000000"
*DISP_LINE_COLOR "255.0000000000"
*DISP_LINE_STYLE "0.0000000000"
*DISP_LINE_WIDTH "0.2500000000"
*DISP_NOTE "Collected Data-2"
*DISP_OFFSET_Y "0.0000000000"
*DISP_PEAKSEARCH_UNIT_Y "cps"
*DISP_RANGE_BOTTOM "0.0000000000"
*DISP_RANGE_LEFT "5.0000000000"
*DISP_RANGE_LOGCUTOFF "0.0100000000"
*DISP_RANGE_RIGHT "89.9960000000"
*DISP_RANGE_TOP "590.4000000000"
*DISP_SCALE_MODE_Y "0.0000000000"
*DISP_TAB_NAME "Theta/2-Theta"
*DISP_TITLE_Y "Intensity"
*DISP_UNIT_Y "cps"
*DISP_WINDOW_NAME "MSG_MACROENGINE"
*FILE_COMMENT " "
*FILE_MD5 ""
*FILE_MEMO " "
*FILE_OPERATOR "administrator"
*FILE_PART_ID "MEAS_KHP2_00072"
*FILE_SAMPLE " "
*FILE_TYPE "RAS_RAW"
*FILE_USERGROUP "System Manager"
*FILE_VERSION "1.0000000000"
*HW_ATTACHMENT_ID "ATT0022"
*HW_ATTACHMENT_NAME "RxRy|RxRy"
*HW_COUNTER_ID-0 "CUT0021"
*HW_COUNTER_ID-1 "CUT0020"
*HW_COUNTER_ID-2 "CUT0020"
*HW_COUNTER_ID-3 "CSL0021"
*HW_COUNTER_ID-4 "CMC0021"
*HW_COUNTER_NAME-0 "SC-70|SC-70"
*HW_COUNTER_NAME-1 "None|None"
*HW_COUNTER_NAME-2 "None|None"
*HW_COUNTER_NAME-3 "BBM|BBM"
*HW_COUNTER_NAME-4 "Detector monochromator|Detector monochromator"
*HW_COUNTER_SELECT_NAME "SC-70|SC-70"
*HW_ECP_HV "689.0000000000"
*HW_ECP_HV_UNIT "V"
*HW_GONIOMETER_ID "GON0024"
*HW_GONIOMETER_NAME "SmartLab(In-plane)|SmartLab(In-plane)"
*HW_GONIOMETER_RADIUS-0 "90.0"
*HW_GONIOMETER_RADIUS-1 "114.0"
*HW_GONIOMETER_RADIUS-2 "190.0"
*HW_GONIOMETER_RADIUS-3 "300.0"
*HW_GONIOMETER_RADIUS-4 "187.0"
*HW_GONIOMETER_RADIUS-5 "300.0"
*HW_GONIOMETER_RADIUS-6 "113.0"
*HW_GONIOMETER_RADIUS-7 "331.0"
*HW_I_OPT_ID-0 "CBO0021"
*HW_I_OPT_ID-1 "ICR0023"
*HW_I_OPT_ID-2 "ISL0021"
*HW_I_OPT_ID-3 "ISO0021"
*HW_I_OPT_ID-4 "IAD0021"
*HW_I_OPT_ID-5 "IPR0001"
*HW_I_OPT_NAME-0 "CBO unit"
*HW_I_OPT_NAME-1 "Standard incident optical unit"
*HW_I_OPT_NAME-2 "Standard incident slit box"
*HW_I_OPT_NAME-3 "Incident parallel slit"
*HW_I_OPT_NAME-4 "Length limiting slit"
*HW_I_OPT_NAME-5 "None|None"
*HW_R_ATTENUATER_AUTOMODE "0"
*HW_R_OPT_ID-0 "RSS0021"
*HW_R_OPT_ID-1 "RCR0022"
*HW_R_OPT_ID-2 "RSO0021"
*HW_R_OPT_ID-3 "RRS0021"
*HW_R_OPT_ID-4 "ATN0021"
*HW_R_OPT_ID-5 "RFL0021"
*HW_R_OPT_ID-6 "RAD0021"
*HW_R_OPT_NAME-0 "Standard receiving slit box # 1"
*HW_R_OPT_NAME-1 "Standard receiving unit # 1"
*HW_R_OPT_NAME-2 "Standard receiving optical unit # 2"
*HW_R_OPT_NAME-3 "Standard receiving slit box # 2"
*HW_R_OPT_NAME-4 "Standard Attenuator"
*HW_R_OPT_NAME-5 "Cu K-beta"
*HW_R_OPT_NAME-6 "Alignment receiving slit"
*HW_SAMPLE_HOLDER_ID "SMP0026"
*HW_SAMPLE_HOLDER_NAME "Z-Phi Stage"
*HW_XG_CURRENT_MAX "50"
*HW_XG_CURRENT_MIN "2"
*HW_XG_CURRENT_RESOLUTION "1"
*HW_XG_CURRENT_UNIT "mA"
*HW_XG_FOCUS "1mm x 10mm"
*HW_XG_FOCUS_TYPE "Normal"
*HW_XG_ID "1200"
*HW_XG_NAME "3kW Sealed tube(ID:1200)"
*HW_XG_TARGET_ATOMIC_NUMBER "29.0000000000"
*HW_XG_TARGET_NAME "Cu"
*HW_XG_TYPE "Hermetic"
*HW_XG_VOLTAGE_MAX "60"
*HW_XG_VOLTAGE_MIN "20"
*HW_XG_VOLTAGE_RESOLUTION "1"
*HW_XG_VOLTAGE_UNIT "kV"
*HW_XG_WATT_MAX "2"
*HW_XG_WATT_UNIT "kW"
*HW_XG_WAVE_LENGTH_ALPHA1 "1.540593"
*HW_XG_WAVE_LENGTH_ALPHA2 "1.544414"
*HW_XG_WAVE_LENGTH_BETA "1.392250"
*MEAS_COND_AXIS_NAME-0 "Theta/2-Theta"
*MEAS_COND_AXIS_NAME-1 "2-Theta"
*MEAS_COND_AXIS_NAME-2 "Omega"
*MEAS_COND_AXIS_NAME-3 "Phi"
*MEAS_COND_AXIS_NAME-4 "Z"
*MEAS_COND_AXIS_NAME-5 "Rx"
*MEAS_COND_AXIS_NAME-6 "Ry"
*MEAS_COND_AXIS_NAME-7 "2-Theta/Omega"
*MEAS_COND_AXIS_NAME-8 "2-ThetaChi"
*MEAS_COND_AXIS_NAME-9 "2-ThetaChi/Phi"
*MEAS_COND_AXIS_NAME-10 "Alpha"
*MEAS_COND_AXIS_NAME-11 "Beta"
*MEAS_COND_AXIS_NAME-12 "Theta_s"
*MEAS_COND_AXIS_NAME-13 "Theta_d"
*MEAS_COND_AXIS_NAME-14 "Ts"
*MEAS_COND_AXIS_NAME-15 "CBO selection slit"
*MEAS_COND_AXIS_NAME-16 "M"
*MEAS_COND_AXIS_NAME-17 "Incident parallel slit"
*MEAS_COND_AXIS_NAME-18 "Incident slit"
*MEAS_COND_AXIS_NAME-19 ""
*MEAS_COND_AXIS_NAME-20 "Zs"
*MEAS_COND_AXIS_NAME-21 "Incident monochromator"
*MEAS_COND_AXIS_NAME-22 "Length limiting slit"
*MEAS_COND_AXIS_NAME-23 "Center slit"
*MEAS_COND_AXIS_NAME-24 "Filter"
*MEAS_COND_AXIS_NAME-25 "Receiving slit # 1"
*MEAS_COND_AXIS_NAME-26 "Receiving slit # 2"
*MEAS_COND_AXIS_NAME-27 "Receiving optical device"
*MEAS_COND_AXIS_NAME-28 "Receiving parallel slit"
*MEAS_COND_AXIS_NAME-29 "Alignment receiving slit"
*MEAS_COND_AXIS_NAME-30 ""
*MEAS_COND_AXIS_NAME-31 ""
*MEAS_COND_AXIS_NAME-32 "Zd"
*MEAS_COND_AXIS_NAME-33 "Attenuator"
*MEAS_COND_AXIS_NAME-34 "Diffracted beam monochromator"
*MEAS_COND_AXIS_NAME-35 "Monochromator slit"
*MEAS_COND_AXIS_NAME-36 "2-ThetaB"
*MEAS_COND_AXIS_NAME-37 "Primary beam"
*MEAS_COND_AXIS_NAME-38 "HV"
*MEAS_COND_AXIS_NAME-39 "PHA"
*MEAS_COND_AXIS_NAME_INTERNAL-0 "TwoThetaTheta"
*MEAS_COND_AXIS_NAME_INTERNAL-1 "TwoTheta"
*MEAS_COND_AXIS_NAME_INTERNAL-2 "Omega"
*MEAS_COND_AXIS_NAME_INTERNAL-3 "Phi"
*MEAS_COND_AXIS_NAME_INTERNAL-4 "Z"
*MEAS_COND_AXIS_NAME_INTERNAL-5 "Rx"
*MEAS_COND_AXIS_NAME_INTERNAL-6 "Ry"
*MEAS_COND_AXIS_NAME_INTERNAL-7 "TwoThetaOmega"
*MEAS_COND_AXIS_NAME_INTERNAL-8 "TwoThetaChi"
*MEAS_COND_AXIS_NAME_INTERNAL-9 "TwoThetaChiPhi"
*MEAS_COND_AXIS_NAME_INTERNAL-10 "Alpha"
*MEAS_COND_AXIS_NAME_INTERNAL-11 "Beta"
*MEAS_COND_AXIS_NAME_INTERNAL-12 "ThetaS"
*MEAS_COND_AXIS_NAME_INTERNAL-13 "ThetaD"
*MEAS_COND_AXIS_NAME_INTERNAL-14 "Ts"
*MEAS_COND_AXIS_NAME_INTERNAL-15 "CBO"
*MEAS_COND_AXIS_NAME_INTERNAL-16 "CBO-M"
*MEAS_COND_AXIS_NAME_INTERNAL-17 "IncidentSollerSlit"
*MEAS_COND_AXIS_NAME_INTERNAL-18 "IncidentSlitBox"
*MEAS_COND_AXIS_NAME_INTERNAL-19 "IncidentSlitBox-_Axis"
*MEAS_COND_AXIS_NAME_INTERNAL-20 "Zs"
*MEAS_COND_AXIS_NAME_INTERNAL-21 "IncidentMonochromator"
*MEAS_COND_AXIS_NAME_INTERNAL-22 "IncidentAxdSlit"
*MEAS_COND_AXIS_NAME_INTERNAL-23 "CenterSlit"
*MEAS_COND_AXIS_NAME_INTERNAL-24 "Filter"
*MEAS_COND_AXIS_NAME_INTERNAL-25 "ReceivingSlitBox1"
*MEAS_COND_AXIS_NAME_INTERNAL-26 "ReceivingSlitBox2"
*MEAS_COND_AXIS_NAME_INTERNAL-27 "ReceivingOptics"
*MEAS_COND_AXIS_NAME_INTERNAL-28 "ReceivingSollerSlit"
*MEAS_COND_AXIS_NAME_INTERNAL-29 "ReceivingAxdSlit"
*MEAS_COND_AXIS_NAME_INTERNAL-30 "ReceivingSlitBox1-_Axis"
*MEAS_COND_AXIS_NAME_INTERNAL-31 "ReceivingSlitBox2-_Axis"
*MEAS_COND_AXIS_NAME_INTERNAL-32 "ReceivingSlitBox2-Zd"
*MEAS_COND_AXIS_NAME_INTERNAL-33 "Attenuator"
*MEAS_COND_AXIS_NAME_INTERNAL-34 "CounterMonochromator"
*MEAS_COND_AXIS_NAME_INTERNAL-35 "CounterSlit"
*MEAS_COND_AXIS_NAME_INTERNAL-36 "TwoThetaB"
*MEAS_COND_AXIS_NAME_INTERNAL-37 "IncidentPrimary"
*MEAS_COND_AXIS_NAME_INTERNAL-38 "HV"
*MEAS_COND_AXIS_NAME_INTERNAL-39 "PHA"
*MEAS_COND_AXIS_NAME_MAGICNO-0 "83951616.0000000000"
*MEAS_COND_AXIS_NAME_MAGICNO-1 "268632064.0000000000"
*MEAS_COND_AXIS_NAME_MAGICNO-2 "268500992.0000000000"
*MEAS_COND_AXIS_NAME_MAGICNO-3 "268500992.0000000000"
*MEAS_COND_AXIS_NAME_MAGICNO-4 "285278208.0000000000"
*MEAS_COND_AXIS_NAME_MAGICNO-5 "285278208.0000000000"
*MEAS_COND_AXIS_NAME_MAGICNO-6 "285278208.0000000000"
*MEAS_COND_AXIS_NAME_MAGICNO-7 "83951616.0000000000"
*MEAS_COND_AXIS_NAME_MAGICNO-8 "268632064.0000000000"
*MEAS_COND_AXIS_NAME_MAGICNO-9 "83951616.0000000000"
*MEAS_COND_AXIS_NAME_MAGICNO-10 "17039360.0000000000"
*MEAS_COND_AXIS_NAME_MAGICNO-11 "17039360.0000000000"
*MEAS_COND_AXIS_NAME_MAGICNO-12 "131072.0000000000"
*MEAS_COND_AXIS_NAME_MAGICNO-13 "131072.0000000000"
*MEAS_COND_AXIS_NAME_MAGICNO-14 "318898176.0000000000"
*MEAS_COND_AXIS_NAME_MAGICNO-15 "20971521.0000000000"
*MEAS_COND_AXIS_NAME_MAGICNO-16 "285343744.0000000000"
*MEAS_COND_AXIS_NAME_MAGICNO-17 "20971521.0000000000"
*MEAS_COND_AXIS_NAME_MAGICNO-18 "22020097.0000000000"
*MEAS_COND_AXIS_NAME_MAGICNO-19 "25165824.0000000000"
*MEAS_COND_AXIS_NAME_MAGICNO-20 "318898176.0000000000"
*MEAS_COND_AXIS_NAME_MAGICNO-21 "1.0000000000"
*MEAS_COND_AXIS_NAME_MAGICNO-22 "20971521.0000000000"
*MEAS_COND_AXIS_NAME_MAGICNO-23 "20971521.0000000000"
*MEAS_COND_AXIS_NAME_MAGICNO-24 "20971521.0000000000"
*MEAS_COND_AXIS_NAME_MAGICNO-25 "23068673.0000000000"
*MEAS_COND_AXIS_NAME_MAGICNO-26 "23068673.0000000000"
*MEAS_COND_AXIS_NAME_MAGICNO-27 "20971521.0000000000"
*MEAS_COND_AXIS_NAME_MAGICNO-28 "20971521.0000000000"
*MEAS_COND_AXIS_NAME_MAGICNO-29 "20971521.0000000000"
*MEAS_COND_AXIS_NAME_MAGICNO-30 "25165824.0000000000"
*MEAS_COND_AXIS_NAME_MAGICNO-31 "25165824.0000000000"
*MEAS_COND_AXIS_NAME_MAGICNO-32 "285343744.0000000000"
*MEAS_COND_AXIS_NAME_MAGICNO-33 "17301505.0000000000"
*MEAS_COND_AXIS_NAME_MAGICNO-34 "20971521.0000000000"
*MEAS_COND_AXIS_NAME_MAGICNO-35 "20971521.0000000000"
*MEAS_COND_AXIS_NAME_MAGICNO-36 "17039360.0000000000"
*MEAS_COND_AXIS_NAME_MAGICNO-37 "20971521.0000000000"
*MEAS_COND_AXIS_NAME_MAGICNO-38 "0.0000000000"
*MEAS_COND_AXIS_NAME_MAGICNO-39 "0.0000000000"
*MEAS_COND_AXIS_OFFSET-0 "-"
*MEAS_COND_AXIS_OFFSET-1 "0.1260000000"
*MEAS_COND_AXIS_OFFSET-2 "0.1220000000"
*MEAS_COND_AXIS_OFFSET-3 "0.0000000000"
*MEAS_COND_AXIS_OFFSET-4 "-"
*MEAS_COND_AXIS_OFFSET-5 "-"
*MEAS_COND_AXIS_OFFSET-6 "-"
*MEAS_COND_AXIS_OFFSET-7 "-"
*MEAS_COND_AXIS_OFFSET-8 "0.0000000000"
*MEAS_COND_AXIS_OFFSET-9 "-"
*MEAS_COND_AXIS_OFFSET-10 "-"
*MEAS_COND_AXIS_OFFSET-11 "-"
*MEAS_COND_AXIS_OFFSET-12 "0.1220000000"
*MEAS_COND_AXIS_OFFSET-13 "0.0040000000"
*MEAS_COND_AXIS_OFFSET-14 "-"
*MEAS_COND_AXIS_OFFSET-15 "-"
*MEAS_COND_AXIS_OFFSET-16 "-"
*MEAS_COND_AXIS_OFFSET-17 "-"
*MEAS_COND_AXIS_OFFSET-18 "-"
*MEAS_COND_AXIS_OFFSET-19 "-"
*MEAS_COND_AXIS_OFFSET-20 "-"
*MEAS_COND_AXIS_OFFSET-21 "-"
*MEAS_COND_AXIS_OFFSET-22 "-"
*MEAS_COND_AXIS_OFFSET-23 "-"
*MEAS_COND_AXIS_OFFSET-24 "-"
*MEAS_COND_AXIS_OFFSET-25 "-"
*MEAS_COND_AXIS_OFFSET-26 "-"
*MEAS_COND_AXIS_OFFSET-27 "-"
*MEAS_COND_AXIS_OFFSET-28 "-"
*MEAS_COND_AXIS_OFFSET-29 "-"
*MEAS_COND_AXIS_OFFSET-30 "-"
*MEAS_COND_AXIS_OFFSET-31 "-"
*MEAS_COND_AXIS_OFFSET-32 "-"
*MEAS_COND_AXIS_OFFSET-33 "-"
*MEAS_COND_AXIS_OFFSET-34 "-"
*MEAS_COND_AXIS_OFFSET-35 "-"
*MEAS_COND_AXIS_OFFSET-36 "-"
*MEAS_COND_AXIS_OFFSET-37 "-"
*MEAS_COND_AXIS_OFFSET-38 "-"
*MEAS_COND_AXIS_OFFSET-39 "-"
*MEAS_COND_AXIS_POSITION-0 "5.0000000000"
*MEAS_COND_AXIS_POSITION-1 "5.0000000000"
*MEAS_COND_AXIS_POSITION-2 "2.5000000000"
*MEAS_COND_AXIS_POSITION-3 "0.0000000000"
*MEAS_COND_AXIS_POSITION-4 "0.0053000000"
*MEAS_COND_AXIS_POSITION-5 "0.0000000000"
*MEAS_COND_AXIS_POSITION-6 "0.0000000000"
*MEAS_COND_AXIS_POSITION-7 "5.0000000000"
*MEAS_COND_AXIS_POSITION-8 "0.0000000000"
*MEAS_COND_AXIS_POSITION-9 "0.0000000000"
*MEAS_COND_AXIS_POSITION-10 "90.0000000000"
*MEAS_COND_AXIS_POSITION-11 "0.0000000000"
*MEAS_COND_AXIS_POSITION-12 "2.5000000000"
*MEAS_COND_AXIS_POSITION-13 "2.5000000000"
*MEAS_COND_AXIS_POSITION-14 "-0.2910600000"
*MEAS_COND_AXIS_POSITION-15 "BB"
*MEAS_COND_AXIS_POSITION-16 "0.0000000000"
*MEAS_COND_AXIS_POSITION-17 "Soller_slit_5.0deg"
*MEAS_COND_AXIS_POSITION-18 "Open"
*MEAS_COND_AXIS_POSITION-19 "7.0000000000"
*MEAS_COND_AXIS_POSITION-20 "0.0150000000"
*MEAS_COND_AXIS_POSITION-21 "0.0000000000"
*MEAS_COND_AXIS_POSITION-22 "2.0mm"
*MEAS_COND_AXIS_POSITION-23 "None"
*MEAS_COND_AXIS_POSITION-24 "Cu_K-beta"
*MEAS_COND_AXIS_POSITION-25 "1/8deg"
*MEAS_COND_AXIS_POSITION-26 "0.300mm"
*MEAS_COND_AXIS_POSITION-27 "PSA_open"
*MEAS_COND_AXIS_POSITION-28 "Soller_slit_5.0deg"
*MEAS_COND_AXIS_POSITION-29 "None"
*MEAS_COND_AXIS_POSITION-30 "0.2463000000"
*MEAS_COND_AXIS_POSITION-31 "0.3000000000"
*MEAS_COND_AXIS_POSITION-32 "0.2725000000"
*MEAS_COND_AXIS_POSITION-33 "Open"
*MEAS_COND_AXIS_POSITION-34 "None"
*MEAS_COND_AXIS_POSITION-35 "None"
*MEAS_COND_AXIS_POSITION-36 "5.0000000000"
*MEAS_COND_AXIS_POSITION-37 "None"
*MEAS_COND_AXIS_POSITION-38 "689.0000000000"
*MEAS_COND_AXIS_POSITION-39 "543.7500000000"
*MEAS_COND_AXIS_UNIT-0 "deg"
*MEAS_COND_AXIS_UNIT-1 "deg"
*MEAS_COND_AXIS_UNIT-2 "deg"
*MEAS_COND_AXIS_UNIT-3 "deg"
*MEAS_COND_AXIS_UNIT-4 "mm"
*MEAS_COND_AXIS_UNIT-5 "deg"
*MEAS_COND_AXIS_UNIT-6 "deg"
*MEAS_COND_AXIS_UNIT-7 "deg"
*MEAS_COND_AXIS_UNIT-8 "deg"
*MEAS_COND_AXIS_UNIT-9 "deg"
*MEAS_COND_AXIS_UNIT-10 "deg"
*MEAS_COND_AXIS_UNIT-11 "deg"
*MEAS_COND_AXIS_UNIT-12 "deg"
*MEAS_COND_AXIS_UNIT-13 "deg"
*MEAS_COND_AXIS_UNIT-14 "mm"
*MEAS_COND_AXIS_UNIT-15 ""
*MEAS_COND_AXIS_UNIT-16 "pulse"
*MEAS_COND_AXIS_UNIT-17 ""
*MEAS_COND_AXIS_UNIT-18 ""
*MEAS_COND_AXIS_UNIT-19 "mm"
*MEAS_COND_AXIS_UNIT-20 "mm"
*MEAS_COND_AXIS_UNIT-21 ""
*MEAS_COND_AXIS_UNIT-22 ""
*MEAS_COND_AXIS_UNIT-23 ""
*MEAS_COND_AXIS_UNIT-24 ""
*MEAS_COND_AXIS_UNIT-25 ""
*MEAS_COND_AXIS_UNIT-26 ""
*MEAS_COND_AXIS_UNIT-27 ""
*MEAS_COND_AXIS_UNIT-28 ""
*MEAS_COND_AXIS_UNIT-29 ""
*MEAS_COND_AXIS_UNIT-30 "mm"
*MEAS_COND_AXIS_UNIT-31 "mm"
*MEAS_COND_AXIS_UNIT-32 "mm"
*MEAS_COND_AXIS_UNIT-33 ""
*MEAS_COND_AXIS_UNIT-34 ""
*MEAS_COND_AXIS_UNIT-35 ""
*MEAS_COND_AXIS_UNIT-36 "deg"
*MEAS_COND_AXIS_UNIT-37 ""
*MEAS_COND_AXIS_UNIT-38 "V"
*MEAS_COND_AXIS_UNIT-39 "mV"
*MEAS_COND_COUNTER_CNTLOSS_CORR "1.0000000000"
*MEAS_COND_COUNTER_PHABASE "543.7500000000"
*MEAS_COND_COUNTER_PHAWINDOW "902.5000000000"
*MEAS_COND_COUNTER_PHA_UNIT "mV"
*MEAS_COND_COUNTER_TAUDIFF "0.1987010000"
*MEAS_COND_COUNTER_TAUINT "0.6706360000"
*MEAS_COND_IRRADIATION_MODE "OFF"
*MEAS_COND_IRRADIATION_WIDTH ""
*MEAS_COND_OPT_ATTR "Bragg-Brentano focusing"
*MEAS_COND_OPT_NAME "@BB focusing"
*MEAS_COND_UNSYMMETRIC_MODE "OFF"
*MEAS_COND_XG_CURRENT "44.0000000000"
*MEAS_COND_XG_VOLTAGE "40.0000000000"
*MEAS_COND_XG_WAVE_TYPE "Ka"
*MEAS_DATA_COUNT "14167.0000000000"
*MEAS_SCAN_AXIS_X "Theta/2-Theta"
*MEAS_SCAN_AXIS_X_INTERNAL "TwoThetaTheta"
*MEAS_SCAN_END_TIME "05/18/18 07:40:58"
*MEAS_SCAN_MODE "STEP"
*MEAS_SCAN_MONITOR "0"
*MEAS_SCAN_RESOLUTION_X "0.0002"
*MEAS_SCAN_SPEED "3.000000"
*MEAS_SCAN_SPEED_UNIT "sec."
*MEAS_SCAN_SPEED_USER "3.00"
*MEAS_SCAN_START "5.0000000000"
*MEAS_SCAN_START_TIME "05/17/18 19:43:57"
*MEAS_SCAN_STEP "0.0060000000"
*MEAS_SCAN_STOP "89.9960000000"
*MEAS_SCAN_UNIT_X "deg"
*MEAS_SCAN_UNIT_Y "counts"
*RAS_HEADER_END
*RAS_INT_START
5.0000 75.0000 1.0000
5.0600 66.0000 1.0000
5.1200 61.0000 1.0000
5.1800 61.0000 1.0000
5.2400 66.0000 1.0000
5.3000 64.0000 1.0000
5.3600 48.0000 1.0000
5.4200 44.0000 1.0000
5.4800 59.0000 1.0000
5.5400 43.0000 1.0000
5.6000 50.0000 1.0000
5.6600 50.0000 1.0000
5.7200 47.0000 1.0000
5.7800 51.0000 1.0000
5.8400 45.0000 1.0000
5.9000 50.0000 1.0000
5.9600 51.0000 1.0000
6.0200 47.0000 1.0000
6.0800 55.0000 1.0000
6.1400 45.0000 1.0000
6.2000 53.0000 1.0000
6.2600 42.0000 1.0000
6.3200 53.0000 1.0000
6.3800 25.0000 1.0000
6.4400 44.0000 1.0000
6.5000 51.0000 1.0000
6.5600 50.0000 1.0000
6.6200 44.0000 1.0000
6.6800 40.0000 1.0000
6.7400 102.0000 1.0000
6.8000 165.0000 1.0000
6.8600 53.0000 1.0000
6.9200 43.0000 1.0000
6.9800 49.0000 1.0000
7.0400 45.0000 1.0000
7.1000 52.0000 1.0000
7.1600 37.0000 1.0000
7.2200 37.0000 1.0000
7.2800 53.0000 1.0000
7.3400 30.0000 1.0000
7.4000 37.0000 1.0000
7.4600 40.0000 1.0000
7.5200 33.0000 1.0000
7.5800 44.0000 1.0000
7.6400 46.0000 1.0000
7.7000 51.0000 1.0000
7.7600 36.0000 1.0000
7.8200 44.0000 1.0000
7.8800 36.0000 1.0000
7.9400 38.0000 1.0000
8.0000 45.0000 1.0000
8.0600 40.0000 1.0000
8.1200 35.0000 1.0000
8.1800 30.0000 1.0000
8.2400 36.0000 1.0000
8.3000 24.0000 1.0000
8.3600 28.0000 1.0000
8.4200 32.0000 1.0000
8.4800 29.0000 1.0000
8.5400 34.0000 1.0000
8.6000 32.0000 1.0000
8.6600 22.0000 1.0000
8.7200 28.0000 1.0000
8.7800 35.0000 1.0000
8.8400 28.0000 1.0000
8.9000 28.0000 1.0000
8.9600 18.0000 1.0000
9.0200 31.0000 1.0000
9.0800 18.0000 1.0000
9.1400 40.0000 1.0000
9.2000 21.0000 1.0000
9.2600 24.0000 1.0000
9.3200 23.0000 1.0000
9.3800 30.0000 1.0000
9.4400 27.0000 1.0000
9.5000 30.0000 1.0000
9.5600 11.0000 1.0000
9.6200 25.0000 1.0000
9.6800 20.0000 1.0000
9.7400 22.0000 1.0000
9.8000 27.0000 1.0000
9.8600 36.0000 1.0000
9.9200 34.0000 1.0000
9.9800 27.0000 1.0000
10.0400 32.0000 1.0000
10.1000 20.0000 1.0000
10.1600 32.0000 1.0000
10.2200 36.0000 1.0000
10.2800 24.0000 1.0000
10.3400 21.0000 1.0000
10.4000 16.0000 1.0000
10.4600 37.0000 1.0000
10.5200 38.0000 1.0000
10.5800 25.0000 1.0000
10.6400 37.0000 1.0000
10.7000 24.0000 1.0000
10.7600 16.0000 1.0000
10.8200 38.0000 1.0000
10.8800 28.0000 1.0000
10.9400 25.0000 1.0000
11.0000 34.0000 1.0000
11.0600 26.0000 1.0000
11.1200 27.0000 1.0000
11.1800 28.0000 1.0000
11.2400 37.0000 1.0000
11.3000 31.0000 1.0000
11.3600 35.0000 1.0000
11.4200 33.0000 1.0000
11.4800 37.0000 1.0000
11.5400 42.0000 1.0000
11.6000 31.0000 1.0000
11.6600 20.0000 1.0000
11.7200 31.0000 1.0000
11.7800 27.0000 1.0000
11.8400 24.0000 1.0000
11.9000 30.0000 1.0000
11.9600 31.0000 1.0000
12.0200 27.0000 1.0000
12.0800 30.0000 1.0000
12.1400 27.0000 1.0000
12.2000 31.0000 1.0000
12.2600 40.0000 1.0000
12.3200 20.0000 1.0000
12.3800 24.0000 1.0000
12.4400 18.0000 1.0000
12.5000 21.0000 1.0000
12.5600 24.0000 1.0000
12.6200 14.0000 1.0000
12.6800 18.0000 1.0000
12.7400 20.0000 1.0000
12.8000 25.0000 1.0000
12.8600 35.0000 1.0000
12.9200 31.0000 1.0000
12.9800 25.0000 1.0000
13.0400 24.0000 1.0000
13.1000 26.0000 1.0000
13.1600 11.0000 1.0000
13.2200 29.0000 1.0000
13.2800 25.0000 1.0000
13.3400 20.0000 1.0000
13.4000 25.0000 1.0000
13.4600 24.0000 1.0000
13.5200 34.0000 1.0000
13.5800 61.0000 1.0000
13.6400 62.0000 1.0000
13.7000 32.0000 1.0000
13.7600 18.0000 1.0000
13.8200 26.0000 1.0000
13.8800 20.0000 1.0000
13.9400 18.0000 1.0000
14.0000 23.0000 1.0000
14.0600 20.0000 1.0000
14.1200 20.0000 1.0000
14.1800 13.0000 1.0000
14.2400 25.0000 1.0000
14.3000 24.0000 1.0000
14.3600 18.0000 1.0000
14.4200 24.0000 1.0000
14.4800 19.0000 1.0000
14.5400 19.0000 1.0000
14.6000 19.0000 1.0000
14.6600 15.0000 1.0000
14.7200 22.0000 1.0000
14.7800 18.0000 1.0000
14.8400 15.0000 1.0000
14.9000 19.0000 1.0000
14.9600 24.0000 1.0000
15.0200 19.0000 1.0000
15.0800 19.0000 1.0000
15.1400 27.0000 1.0000
15.2000 19.0000 1.0000
15.2600 30.0000 1.0000
15.3200 17.0000 1.0000
15.3800 19.0000 1.0000
15.4400 19.0000 1.0000
15.5000 29.0000 1.0000
15.5600 28.0000 1.0000
15.6200 17.0000 1.0000
15.6800 18.0000 1.0000
15.7400 20.0000 1.0000
15.8000 28.0000 1.0000
15.8600 18.0000 1.0000
15.9200 23.0000 1.0000
15.9800 25.0000 1.0000
16.0400 18.0000 1.0000
16.1000 17.0000 1.0000
16.1600 18.0000 1.0000
16.2200 11.0000 1.0000
16.2800 14.0000 1.0000
16.3400 21.0000 1.0000
16.4000 10.0000 1.0000
16.4600 21.0000 1.0000
16.5200 18.0000 1.0000
16.5800 27.0000 1.0000
16.6400 20.0000 1.0000
16.7000 11.0000 1.0000
16.7600 19.0000 1.0000
16.8200 19.0000 1.0000
16.8800 14.0000 1.0000
16.9400 20.0000 1.0000
17.0000 28.0000 1.0000
17.0600 19.0000 1.0000
17.1200 16.0000 1.0000
17.1800 13.0000 1.0000
17.2400 18.0000 1.0000
17.3000 21.0000 1.0000
17.3600 17.0000 1.0000
17.4200 18.0000 1.0000
17.4800 12.0000 1.0000
17.5400 22.0000 1.0000
17.6000 13.0000 1.0000
17.6600 20.0000 1.0000
17.7200 17.0000 1.0000
17.7800 9.0000 1.0000
17.8400 18.0000 1.0000
17.9000 17.0000 1.0000
17.9600 16.0000 1.0000
18.0200 20.0000 1.0000
18.0800 20.0000 1.0000
18.1400 13.0000 1.0000
18.2000 15.0000 1.0000
18.2600 15.0000 1.0000
18.3200 10.0000 1.0000
18.3800 4.0000 1.0000
18.4400 18.0000 1.0000
18.5000 15.0000 1.0000
18.5600 17.0000 1.0000
18.6200 11.0000 1.0000
18.6800 13.0000 1.0000
18.7400 20.0000 1.0000
18.8000 26.0000 1.0000
18.8600 15.0000 1.0000
18.9200 11.0000 1.0000
18.9800 17.0000 1.0000
19.0400 22.0000 1.0000
19.1000 21.0000 1.0000
19.1600 15.0000 1.0000
19.2200 19.0000 1.0000
19.2800 10.0000 1.0000
19.3400 17.0000 1.0000
19.4000 19.0000 1.0000
19.4600 14.0000 1.0000
19.5200 21.0000 1.0000
19.5800 15.0000 1.0000
19.6400 16.0000 1.0000
19.7000 32.0000 1.0000
19.7600 34.0000 1.0000
19.8200 14.0000 1.0000
19.8800 18.0000 1.0000
19.9400 11.0000 1.0000
20.0000 18.0000 1.0000
20.0600 16.0000 1.0000
20.1200 11.0000 1.0000
20.1800 15.0000 1.0000
20.2400 20.0000 1.0000
20.3000 18.0000 1.0000
20.3600 16.0000 1.0000
20.4200 49.0000 1.0000
20.4800 154.0000 1.0000
20.5400 113.0000 1.0000
20.6000 25.0000 1.0000
20.6600 11.0000 1.0000
20.7200 18.0000 1.0000
20.7800 25.0000 1.0000
20.8400 19.0000 1.0000
20.9000 17.0000 1.0000
20.9600 18.0000 1.0000
21.0200 11.0000 1.0000
21.0800 16.0000 1.0000
21.1400 10.0000 1.0000
21.2000 12.0000 1.0000
21.2600 18.0000 1.0000
21.3200 10.0000 1.0000
21.3800 15.0000 1.0000
21.4400 23.0000 1.0000
21.5000 20.0000 1.0000
21.5600 19.0000 1.0000
21.6200 15.0000 1.0000
21.6800 11.0000 1.0000
21.7400 16.0000 1.0000
21.8000 17.0000 1.0000
21.8600 6.0000 1.0000
21.9200 11.0000 1.0000
21.9800 10.0000 1.0000
22.0400 20.0000 1.0000
22.1000 16.0000 1.0000
22.1600 18.0000 1.0000
22.2200 14.0000 1.0000
22.2800 21.0000 1.0000
22.3400 14.0000 1.0000
22.4000 15.0000 1.0000
22.4600 7.0000 1.0000
22.5200 16.0000 1.0000
22.5800 13.0000 1.0000
22.6400 14.0000 1.0000
22.7000 14.0000 1.0000
22.7600 16.0000 1.0000
22.8200 35.0000 1.0000
22.8800 29.0000 1.0000
22.9400 62.0000 1.0000
23.0000 169.0000 1.0000
23.0600 556.0000 1.0000
23.1200 282.0000 1.0000
23.1800 40.0000 1.0000
23.2400 21.0000 1.0000
23.3000 20.0000 1.0000
23.3600 16.0000 1.0000
23.4200 13.0000 1.0000
23.4800 16.0000 1.0000
23.5400 12.0000 1.0000
23.6000 11.0000 1.0000
23.6600 9.0000 1.0000
23.7200 11.0000 1.0000
23.7800 12.0000 1.0000
23.8400 14.0000 1.0000
23.9000 10.0000 1.0000
23.9600 12.0000 1.0000
24.0200 10.0000 1.0000
24.0800 6.0000 1.0000
24.1400 18.0000 1.0000
24.2000 17.0000 1.0000
24.2600 9.0000 1.0000
24.3200 12.0000 1.0000
24.3800 13.0000 1.0000
24.4400 17.0000 1.0000
24.5000 22.0000 1.0000
24.5600 8.0000 1.0000
24.6200 12.0000 1.0000
24.6800 16.0000 1.0000
24.7400 12.0000 1.0000
24.8000 12.0000 1.0000
24.8600 13.0000 1.0000
24.9200 11.0000 1.0000
24.9800 15.0000 1.0000
25.0400 10.0000 1.0000
25.1000 15.0000 1.0000
25.1600 16.0000 1.0000
25.2200 9.0000 1.0000
25.2800 14.0000 1.0000
25.3400 18.0000 1.0000
25.4000 11.0000 1.0000
25.4600 10.0000 1.0000
25.5200 13.0000 1.0000
25.5800 14.0000 1.0000
25.6400 11.0000 1.0000
25.7000 10.0000 1.0000
25.7600 16.0000 1.0000
25.8200 15.0000 1.0000
25.8800 13.0000 1.0000
25.9400 16.0000 1.0000
26.0000 11.0000 1.0000
26.0600 10.0000 1.0000
26.1200 14.0000 1.0000
26.1800 8.0000 1.0000
26.2400 14.0000 1.0000
26.3000 10.0000 1.0000
26.3600 22.0000 1.0000
26.4200 10.0000 1.0000
26.4800 13.0000 1.0000
26.5400 17.0000 1.0000
26.6000 11.0000 1.0000
26.6600 15.0000 1.0000
26.7200 13.0000 1.0000
26.7800 14.0000 1.0000
26.8400 14.0000 1.0000
26.9000 11.0000 1.0000
26.9600 10.0000 1.0000
27.0200 12.0000 1.0000
27.0800 9.0000 1.0000
27.1400 17.0000 1.0000
27.2000 16.0000 1.0000
27.2600 21.0000 1.0000
27.3200 27.0000 1.0000
27.3800 37.0000 1.0000
27.4400 135.0000 1.0000
27.5000 79.0000 1.0000
27.5600 73.0000 1.0000
27.6200 42.0000 1.0000
27.6800 103.0000 1.0000
27.7400 369.0000 1.0000
27.8000 233.0000 1.0000
27.8600 26.0000 1.0000
27.9200 19.0000 1.0000
27.9800 16.0000 1.0000
28.0400 13.0000 1.0000
28.1000 10.0000 1.0000
28.1600 20.0000 1.0000
28.2200 12.0000 1.0000
28.2800 16.0000 1.0000
28.3400 14.0000 1.0000
28.4000 12.0000 1.0000
28.4600 11.0000 1.0000
28.5200 15.0000 1.0000
28.5800 15.0000 1.0000
28.6400 15.0000 1.0000
28.7000 15.0000 1.0000
28.7600 9.0000 1.0000
28.8200 10.0000 1.0000
28.8800 11.0000 1.0000
28.9400 16.0000 1.0000
29.0000 14.0000 1.0000
29.0600 18.0000 1.0000
29.1200 14.0000 1.0000
29.1800 13.0000 1.0000
29.2400 13.0000 1.0000
29.3000 17.0000 1.0000
29.3600 15.0000 1.0000
29.4200 16.0000 1.0000
29.4800 8.0000 1.0000
29.5400 13.0000 1.0000
29.6000 10.0000 1.0000
29.6600 11.0000 1.0000
29.7200 10.0000 1.0000
29.7800 7.0000 1.0000
29.8400 14.0000 1.0000
29.9000 12.0000 1.0000
29.9600 13.0000 1.0000
30.0200 14.0000 1.0000
30.0800 9.0000 1.0000
30.1400 12.0000 1.0000
30.2000 15.0000 1.0000
30.2600 14.0000 1.0000
30.3200 6.0000 1.0000
30.3800 19.0000 1.0000
30.4400 13.0000 1.0000
30.5000 13.0000 1.0000
30.5600 11.0000 1.0000
30.6200 15.0000 1.0000
30.6800 7.0000 1.0000
30.7400 5.0000 1.0000
30.8000 9.0000 1.0000
30.8600 11.0000 1.0000
30.9200 9.0000 1.0000
30.9800 9.0000 1.0000
31.0400 9.0000 1.0000
31.1000 23.0000 1.0000
31.1600 11.0000 1.0000
31.2200 13.0000 1.0000
31.2800 9.0000 1.0000
31.3400 11.0000 1.0000
31.4000 10.0000 1.0000
31.4600 13.0000 1.0000
31.5200 19.0000 1.0000
31.5800 15.0000 1.0000
31.6400 11.0000 1.0000
31.7000 8.0000 1.0000
31.7600 13.0000 1.0000
31.8200 16.0000 1.0000
31.8800 11.0000 1.0000
31.9400 10.0000 1.0000
32.0000 13.0000 1.0000
32.0600 12.0000 1.0000
32.1200 19.0000 1.0000
32.1800 37.0000 1.0000
32.2400 60.0000 1.0000
32.3000 78.0000 1.0000
32.3600 89.0000 1.0000
32.4200 64.0000 1.0000
32.4800 35.0000 1.0000
32.5400 15.0000 1.0000
32.6000 13.0000 1.0000
32.6600 15.0000 1.0000
32.7200 17.0000 1.0000
32.7800 17.0000 1.0000
32.8400 7.0000 1.0000
32.9000 13.0000 1.0000
32.9600 9.0000 1.0000
33.0200 11.0000 1.0000
33.0800 34.0000 1.0000
33.1400 45.0000 1.0000
33.2000 54.0000 1.0000
33.2600 220.0000 1.0000
33.3200 514.0000 1.0000
33.3800 208.0000 1.0000
33.4400 108.0000 1.0000
33.5000 32.0000 1.0000
33.5600 19.0000 1.0000
33.6200 18.0000 1.0000
33.6800 10.0000 1.0000
33.7400 17.0000 1.0000
33.8000 22.0000 1.0000
33.8600 23.0000 1.0000
33.9200 12.0000 1.0000
33.9800 12.0000 1.0000
34.0400 12.0000 1.0000
34.1000 5.0000 1.0000
34.1600 14.0000 1.0000
34.2200 12.0000 1.0000
34.2800 15.0000 1.0000
34.3400 22.0000 1.0000
34.4000 53.0000 1.0000
34.4600 51.0000 1.0000
34.5200 336.0000 1.0000
34.5800 74.0000 1.0000
34.6400 136.0000 1.0000
34.7000 14.0000 1.0000
34.7600 10.0000 1.0000
34.8200 21.0000 1.0000
34.8800 10.0000 1.0000
34.9400 15.0000 1.0000
35.0000 21.0000 1.0000
35.0600 6.0000 1.0000
35.1200 15.0000 1.0000
35.1800 20.0000 1.0000
35.2400 15.0000 1.0000
35.3000 13.0000 1.0000
35.3600 11.0000 1.0000
35.4200 2.0000 1.0000
35.4800 12.0000 1.0000
35.5400 13.0000 1.0000
35.6000 10.0000 1.0000
35.6600 14.0000 1.0000
35.7200 11.0000 1.0000
35.7800 13.0000 1.0000
35.8400 8.0000 1.0000
35.9000 12.0000 1.0000
35.9600 5.0000 1.0000
36.0200 12.0000 1.0000
36.0800 11.0000 1.0000
36.1400 6.0000 1.0000
36.2000 11.0000 1.0000
36.2600 9.0000 1.0000
36.3200 3.0000 1.0000
36.3800 15.0000 1.0000
36.4400 10.0000 1.0000
36.5000 8.0000 1.0000
36.5600 9.0000 1.0000
36.6200 11.0000 1.0000
36.6800 12.0000 1.0000
36.7400 8.0000 1.0000
36.8000 8.0000 1.0000
36.8600 16.0000 1.0000
36.9200 15.0000 1.0000
36.9800 9.0000 1.0000
37.0400 11.0000 1.0000
37.1000 9.0000 1.0000
37.1600 8.0000 1.0000
37.2200 10.0000 1.0000
37.2800 11.0000 1.0000
37.3400 7.0000 1.0000
37.4000 15.0000 1.0000
37.4600 8.0000 1.0000
37.5200 7.0000 1.0000
37.5800 9.0000 1.0000
37.6400 11.0000 1.0000
37.7000 5.0000 1.0000
37.7600 9.0000 1.0000
37.8200 13.0000 1.0000
37.8800 9.0000 1.0000
37.9400 11.0000 1.0000
38.0000 9.0000 1.0000
38.0600 9.0000 1.0000
38.1200 15.0000 1.0000
38.1800 10.0000 1.0000
38.2400 10.0000 1.0000
38.3000 10.0000 1.0000
38.3600 9.0000 1.0000
38.4200 9.0000 1.0000
38.4800 6.0000 1.0000
38.5400 8.0000 1.0000
38.6000 12.0000 1.0000
38.6600 6.0000 1.0000
38.7200 8.0000 1.0000
38.7800 7.0000 1.0000
38.8400 12.0000 1.0000
38.9000 12.0000 1.0000
38.9600 10.0000 1.0000
39.0200 9.0000 1.0000
39.0800 13.0000 1.0000
39.1400 7.0000 1.0000
39.2000 5.0000 1.0000
39.2600 16.0000 1.0000
39.3200 10.0000 1.0000
39.3800 14.0000 1.0000
39.4400 27.0000 1.0000
39.5000 10.0000 1.0000
39.5600 20.0000 1.0000
39.6200 9.0000 1.0000
39.6800 9.0000 1.0000
39.7400 7.0000 1.0000
39.8000 4.0000 1.0000
39.8600 6.0000 1.0000
39.9200 10.0000 1.0000
39.9800 11.0000 1.0000
40.0400 12.0000 1.0000
40.1000 10.0000 1.0000
40.1600 3.0000 1.0000
40.2200 11.0000 1.0000
40.2800 8.0000 1.0000
40.3400 8.0000 1.0000
40.4000 7.0000 1.0000
40.4600 8.0000 1.0000
40.5200 11.0000 1.0000
40.5800 7.0000 1.0000
40.6400 14.0000 1.0000
40.7000 3.0000 1.0000
40.7600 6.0000 1.0000
40.8200 8.0000 1.0000
40.8800 12.0000 1.0000
40.9400 10.0000 1.0000
41.0000 8.0000 1.0000
41.0600 7.0000 1.0000
41.1200 5.0000 1.0000
41.1800 8.0000 1.0000
41.2400 9.0000 1.0000
41.3000 8.0000 1.0000
41.3600 5.0000 1.0000
41.4200 10.0000 1.0000
41.4800 8.0000 1.0000
41.5400 7.0000 1.0000
41.6000 12.0000 1.0000
41.6600 11.0000 1.0000
41.7200 19.0000 1.0000
41.7800 12.0000 1.0000
41.8400 15.0000 1.0000
41.9000 10.0000 1.0000
41.9600 9.0000 1.0000
42.0200 10.0000 1.0000
42.0800 6.0000 1.0000
42.1400 5.0000 1.0000
42.2000 3.0000 1.0000
42.2600 7.0000 1.0000
42.3200 11.0000 1.0000
42.3800 22.0000 1.0000
42.4400 17.0000 1.0000
42.5000 10.0000 1.0000
42.5600 9.0000 1.0000
42.6200 8.0000 1.0000
42.6800 10.0000 1.0000
42.7400 9.0000 1.0000
42.8000 7.0000 1.0000
42.8600 4.0000 1.0000
42.9200 16.0000 1.0000
42.9800 7.0000 1.0000
43.0400 10.0000 1.0000
43.1000 9.0000 1.0000
43.1600 17.0000 1.0000
43.2200 10.0000 1.0000
43.2800 8.0000 1.0000
43.3400 10.0000 1.0000
43.4000 10.0000 1.0000
43.4600 14.0000 1.0000
43.5200 7.0000 1.0000
43.5800 10.0000 1.0000
43.6400 6.0000 1.0000
43.7000 8.0000 1.0000
43.7600 7.0000 1.0000
43.8200 9.0000 1.0000
43.8800 9.0000 1.0000
43.9400 15.0000 1.0000
44.0000 12.0000 1.0000
44.0600 8.0000 1.0000
44.1200 10.0000 1.0000
44.1800 19.0000 1.0000
44.2400 14.0000 1.0000
44.3000 7.0000 1.0000
44.3600 10.0000 1.0000
44.4200 5.0000 1.0000
44.4800 4.0000 1.0000
44.5400 6.0000 1.0000
44.6000 5.0000 1.0000
44.6600 6.0000 1.0000
44.7200 5.0000 1.0000
44.7800 7.0000 1.0000
44.8400 6.0000 1.0000
44.9000 11.0000 1.0000
44.9600 6.0000 1.0000
45.0200 13.0000 1.0000
45.0800 8.0000 1.0000
45.1400 9.0000 1.0000
45.2000 7.0000 1.0000
45.2600 15.0000 1.0000
45.3200 7.0000 1.0000
45.3800 12.0000 1.0000
45.4400 11.0000 1.0000
45.5000 13.0000 1.0000
45.5600 11.0000 1.0000
45.6200 10.0000 1.0000
45.6800 14.0000 1.0000
45.7400 8.0000 1.0000
45.8000 11.0000 1.0000
45.8600 16.0000 1.0000
45.9200 22.0000 1.0000
45.9800 22.0000 1.0000
46.0400 14.0000 1.0000
46.1000 22.0000 1.0000
46.1600 10.0000 1.0000
46.2200 12.0000 1.0000
46.2800 9.0000 1.0000
46.3400 8.0000 1.0000
46.4000 9.0000 1.0000
46.4600 1.0000 1.0000
46.5200 10.0000 1.0000
46.5800 17.0000 1.0000
46.6400 13.0000 1.0000
46.7000 13.0000 1.0000
46.7600 20.0000 1.0000
46.8200 18.0000 1.0000
46.8800 13.0000 1.0000
46.9400 47.0000 1.0000
47.0000 82.0000 1.0000
47.0600 140.0000 1.0000
47.1200 465.0000 1.0000
47.1800 1409.0000 1.0000
47.2400 281.0000 1.0000
47.3000 778.0000 1.0000
47.3600 81.0000 1.0000
47.4200 32.0000 1.0000
47.4800 20.0000 1.0000
47.5400 16.0000 1.0000
47.6000 11.0000 1.0000
47.6600 20.0000 1.0000
47.7200 16.0000 1.0000
47.7800 13.0000 1.0000
47.8400 8.0000 1.0000
47.9000 12.0000 1.0000
47.9600 11.0000 1.0000
48.0200 13.0000 1.0000
48.0800 10.0000 1.0000
48.1400 5.0000 1.0000
48.2000 15.0000 1.0000
48.2600 12.0000 1.0000
48.3200 17.0000 1.0000
48.3800 8.0000 1.0000
48.4400 7.0000 1.0000
48.5000 10.0000 1.0000
48.5600 12.0000 1.0000
48.6200 13.0000 1.0000
48.6800 8.0000 1.0000
48.7400 10.0000 1.0000
48.8000 13.0000 1.0000
48.8600 16.0000 1.0000
48.9200 7.0000 1.0000
48.9800 17.0000 1.0000
49.0400 19.0000 1.0000
49.1000 23.0000 1.0000
49.1600 11.0000 1.0000
49.2200 20.0000 1.0000
49.2800 6.0000 1.0000
49.3400 8.0000 1.0000
49.4000 9.0000 1.0000
49.4600 9.0000 1.0000
49.5200 7.0000 1.0000
49.5800 8.0000 1.0000
49.6400 8.0000 1.0000
49.7000 6.0000 1.0000
49.7600 9.0000 1.0000
49.8200 7.0000 1.0000
49.8800 8.0000 1.0000
49.9400 7.0000 1.0000
50.0000 6.0000 1.0000
50.0600 7.0000 1.0000
50.1200 14.0000 1.0000
50.1800 7.0000 1.0000
50.2400 12.0000 1.0000
50.3000 5.0000 1.0000
50.3600 10.0000 1.0000
50.4200 9.0000 1.0000
50.4800 10.0000 1.0000
50.5400 4.0000 1.0000
50.6000 13.0000 1.0000
50.6600 8.0000 1.0000
50.7200 11.0000 1.0000
50.7800 7.0000 1.0000
50.8400 16.0000 1.0000
50.9000 11.0000 1.0000
50.9600 11.0000 1.0000
51.0200 11.0000 1.0000
51.0800 15.0000 1.0000
51.1400 7.0000 1.0000
51.2000 9.0000 1.0000
51.2600 8.0000 1.0000
51.3200 12.0000 1.0000
51.3800 13.0000 1.0000
51.4400 6.0000 1.0000
51.5000 12.0000 1.0000
51.5600 5.0000 1.0000
51.6200 6.0000 1.0000
51.6800 12.0000 1.0000
51.7400 8.0000 1.0000
51.8000 5.0000 1.0000
51.8600 14.0000 1.0000
51.9200 9.0000 1.0000
51.9800 15.0000 1.0000
52.0400 10.0000 1.0000
52.1000 17.0000 1.0000
52.1600 9.0000 1.0000
52.2200 9.0000 1.0000
52.2800 3.0000 1.0000
52.3400 9.0000 1.0000
52.4000 19.0000 1.0000
52.4600 15.0000 1.0000
52.5200 19.0000 1.0000
52.5800 24.0000 1.0000
52.6400 19.0000 1.0000
52.7000 10.0000 1.0000
52.7600 9.0000 1.0000
52.8200 10.0000 1.0000
52.8800 15.0000 1.0000
52.9400 28.0000 1.0000
53.0000 16.0000 1.0000
53.0600 33.0000 1.0000
53.1200 11.0000 1.0000
53.1800 17.0000 1.0000
53.2400 13.0000 1.0000
53.3000 5.0000 1.0000
53.3600 14.0000 1.0000
53.4200 8.0000 1.0000
53.4800 5.0000 1.0000
53.5400 4.0000 1.0000
53.6000 10.0000 1.0000
53.6600 16.0000 1.0000
53.7200 29.0000 1.0000
53.7800 41.0000 1.0000
53.8400 58.0000 1.0000
53.9000 31.0000 1.0000
53.9600 18.0000 1.0000
54.0200 23.0000 1.0000
54.0800 12.0000 1.0000
54.1400 7.0000 1.0000
54.2000 13.0000 1.0000
54.2600 7.0000 1.0000
54.3200 5.0000 1.0000
54.3800 10.0000 1.0000
54.4400 6.0000 1.0000
54.5000 8.0000 1.0000
54.5600 5.0000 1.0000
54.6200 3.0000 1.0000
54.6800 12.0000 1.0000
54.7400 8.0000 1.0000
54.8000 13.0000 1.0000
54.8600 10.0000 1.0000
54.9200 13.0000 1.0000
54.9800 60.0000 1.0000
55.0400 23.0000 1.0000
55.1000 38.0000 1.0000
55.1600 16.0000 1.0000
55.2200 17.0000 1.0000
55.2800 3.0000 1.0000
55.3400 10.0000 1.0000
55.4000 9.0000 1.0000
55.4600 11.0000 1.0000
55.5200 5.0000 1.0000
55.5800 10.0000 1.0000
55.6400 7.0000 1.0000
55.7000 11.0000 1.0000
55.7600 11.0000 1.0000
55.8200 3.0000 1.0000
55.8800 9.0000 1.0000
55.9400 10.0000 1.0000
56.0000 9.0000 1.0000
56.0600 13.0000 1.0000
56.1200 7.0000 1.0000
56.1800 13.0000 1.0000
56.2400 3.0000 1.0000
56.3000 3.0000 1.0000
56.3600 6.0000 1.0000
56.4200 7.0000 1.0000
56.4800 10.0000 1.0000
56.5400 12.0000 1.0000
56.6000 6.0000 1.0000
56.6600 5.0000 1.0000
56.7200 10.0000 1.0000
56.7800 10.0000 1.0000
56.8400 12.0000 1.0000
56.9000 10.0000 1.0000
56.9600 3.0000 1.0000
57.0200 6.0000 1.0000
57.0800 7.0000 1.0000
57.1400 6.0000 1.0000
57.2000 10.0000 1.0000
57.2600 7.0000 1.0000
57.3200 17.0000 1.0000
57.3800 29.0000 1.0000
57.4400 10.0000 1.0000
57.5000 19.0000 1.0000
57.5600 11.0000 1.0000
57.6200 14.0000 1.0000
57.6800 9.0000 1.0000
57.7400 14.0000 1.0000
57.8000 17.0000 1.0000
57.8600 9.0000 1.0000
57.9200 10.0000 1.0000
57.9800 5.0000 1.0000
58.0400 14.0000 1.0000
58.1000 17.0000 1.0000
58.1600 9.0000 1.0000
58.2200 16.0000 1.0000
58.2800 17.0000 1.0000
58.3400 22.0000 1.0000
58.4000 23.0000 1.0000
58.4600 20.0000 1.0000
58.5200 17.0000 1.0000
58.5800 17.0000 1.0000
58.6400 17.0000 1.0000
58.7000 9.0000 1.0000
58.7600 11.0000 1.0000
58.8200 10.0000 1.0000
58.8800 5.0000 1.0000
58.9400 12.0000 1.0000
59.0000 12.0000 1.0000
59.0600 11.0000 1.0000
59.1200 14.0000 1.0000
59.1800 10.0000 1.0000
59.2400 10.0000 1.0000
59.3000 9.0000 1.0000
59.3600 7.0000 1.0000
59.4200 5.0000 1.0000
59.4800 3.0000 1.0000
59.5400 11.0000 1.0000
59.6000 10.0000 1.0000
59.6600 12.0000 1.0000
59.7200 16.0000 1.0000
59.7800 22.0000 1.0000
59.8400 26.0000 1.0000
59.9000 38.0000 1.0000
59.9600 118.0000 1.0000
60.0200 501.0000 1.0000
60.0800 729.0000 1.0000
60.1400 225.0000 1.0000
60.2000 348.0000 1.0000
60.2600 265.0000 1.0000
60.3200 50.0000 1.0000
60.3800 53.0000 1.0000
60.4400 17.0000 1.0000
60.5000 13.0000 1.0000
60.5600 14.0000 1.0000
60.6200 10.0000 1.0000
60.6800 9.0000 1.0000
60.7400 9.0000 1.0000
60.8000 7.0000 1.0000
60.8600 7.0000 1.0000
60.9200 14.0000 1.0000
60.9800 7.0000 1.0000
61.0400 4.0000 1.0000
61.1000 5.0000 1.0000
61.1600 15.0000 1.0000
61.2200 10.0000 1.0000
61.2800 10.0000 1.0000
61.3400 3.0000 1.0000
61.4000 4.0000 1.0000
61.4600 8.0000 1.0000
61.5200 8.0000 1.0000
61.5800 4.0000 1.0000
61.6400 5.0000 1.0000
61.7000 11.0000 1.0000
61.7600 8.0000 1.0000
61.8200 10.0000 1.0000
61.8800 7.0000 1.0000
61.9400 5.0000 1.0000
62.0000 6.0000 1.0000
62.0600 3.0000 1.0000
62.1200 12.0000 1.0000
62.1800 6.0000 1.0000
62.2400 10.0000 1.0000
62.3000 7.0000 1.0000
62.3600 8.0000 1.0000
62.4200 10.0000 1.0000
62.4800 8.0000 1.0000
62.5400 14.0000 1.0000
62.6000 6.0000 1.0000
62.6600 10.0000 1.0000
62.7200 10.0000 1.0000
62.7800 11.0000 1.0000
62.8400 10.0000 1.0000
62.9000 7.0000 1.0000
62.9600 10.0000 1.0000
63.0200 6.0000 1.0000
63.0800 10.0000 1.0000
63.1400 4.0000 1.0000
63.2000 7.0000 1.0000
63.2600 6.0000 1.0000
63.3200 4.0000 1.0000
63.3800 9.0000 1.0000
63.4400 12.0000 1.0000
63.5000 6.0000 1.0000
63.5600 12.0000 1.0000
63.6200 2.0000 1.0000
63.6800 7.0000 1.0000
63.7400 5.0000 1.0000
63.8000 9.0000 1.0000
63.8600 4.0000 1.0000
63.9200 7.0000 1.0000
63.9800 5.0000 1.0000
64.0400 5.0000 1.0000
64.1000 8.0000 1.0000
64.1600 7.0000 1.0000
64.2200 10.0000 1.0000
64.2800 10.0000 1.0000
64.3400 9.0000 1.0000
64.4000 2.0000 1.0000
64.4600 7.0000 1.0000
64.5200 3.0000 1.0000
64.5800 7.0000 1.0000
64.6400 8.0000 1.0000
64.7000 7.0000 1.0000
64.7600 4.0000 1.0000
64.8200 6.0000 1.0000
64.8800 3.0000 1.0000
64.9400 3.0000 1.0000
65.0000 5.0000 1.0000
65.0600 8.0000 1.0000
65.1200 5.0000 1.0000
65.1800 7.0000 1.0000
65.2400 6.0000 1.0000
65.3000 10.0000 1.0000
65.3600 6.0000 1.0000
65.4200 7.0000 1.0000
65.4800 15.0000 1.0000
65.5400 9.0000 1.0000
65.6000 10.0000 1.0000
65.6600 13.0000 1.0000
65.7200 13.0000 1.0000
65.7800 7.0000 1.0000
65.8400 10.0000 1.0000
65.9000 9.0000 1.0000
65.9600 11.0000 1.0000
66.0200 8.0000 1.0000
66.0800 4.0000 1.0000
66.1400 5.0000 1.0000
66.2000 10.0000 1.0000
66.2600 8.0000 1.0000
66.3200 7.0000 1.0000
66.3800 8.0000 1.0000
66.4400 6.0000 1.0000
66.5000 8.0000 1.0000
66.5600 6.0000 1.0000
66.6200 2.0000 1.0000
66.6800 6.0000 1.0000
66.7400 9.0000 1.0000
66.8000 14.0000 1.0000
66.8600 25.0000 1.0000
66.9200 23.0000 1.0000
66.9800 18.0000 1.0000
67.0400 11.0000 1.0000
67.1000 20.0000 1.0000
67.1600 14.0000 1.0000
67.2200 9.0000 1.0000
67.2800 9.0000 1.0000
67.3400 16.0000 1.0000
67.4000 34.0000 1.0000
67.4600 43.0000 1.0000
67.5200 103.0000 1.0000
67.5800 27.0000 1.0000
67.6400 24.0000 1.0000
67.7000 77.0000 1.0000
67.7600 18.0000 1.0000
67.8200 16.0000 1.0000
67.8800 24.0000 1.0000
67.9400 14.0000 1.0000
68.0000 22.0000 1.0000
68.0600 12.0000 1.0000
68.1200 6.0000 1.0000
68.1800 11.0000 1.0000
68.2400 7.0000 1.0000
68.3000 8.0000 1.0000
68.3600 12.0000 1.0000
68.4200 13.0000 1.0000
68.4800 10.0000 1.0000
68.5400 6.0000 1.0000
68.6000 9.0000 1.0000
68.6600 5.0000 1.0000
68.7200 7.0000 1.0000
68.7800 4.0000 1.0000
68.8400 9.0000 1.0000
68.9000 12.0000 1.0000
68.9600 3.0000 1.0000
69.0200 17.0000 1.0000
69.0800 6.0000 1.0000
69.1400 12.0000 1.0000
69.2000 10.0000 1.0000
69.2600 8.0000 1.0000
69.3200 12.0000 1.0000
69.3800 7.0000 1.0000
69.4400 9.0000 1.0000
69.5000 4.0000 1.0000
69.5600 7.0000 1.0000
69.6200 9.0000 1.0000
69.6800 14.0000 1.0000
69.7400 11.0000 1.0000
69.8000 10.0000 1.0000
69.8600 11.0000 1.0000
69.9200 21.0000 1.0000
69.9800 32.0000 1.0000
70.0400 73.0000 1.0000
70.1000 126.0000 1.0000
70.1600 33.0000 1.0000
70.2200 44.0000 1.0000
70.2800 109.0000 1.0000
70.3400 23.0000 1.0000
70.4000 11.0000 1.0000
70.4600 6.0000 1.0000
70.5200 7.0000 1.0000
70.5800 11.0000 1.0000
70.6400 8.0000 1.0000
70.7000 8.0000 1.0000
70.7600 7.0000 1.0000
70.8200 11.0000 1.0000
70.8800 7.0000 1.0000
70.9400 5.0000 1.0000
71.0000 6.0000 1.0000
71.0600 4.0000 1.0000
71.1200 7.0000 1.0000
71.1800 5.0000 1.0000
71.2400 7.0000 1.0000
71.3000 8.0000 1.0000
71.3600 5.0000 1.0000
71.4200 6.0000 1.0000
71.4800 5.0000 1.0000
71.5400 10.0000 1.0000
71.6000 5.0000 1.0000
71.6600 7.0000 1.0000
71.7200 4.0000 1.0000
71.7800 3.0000 1.0000
71.8400 4.0000 1.0000
71.9000 9.0000 1.0000
71.9600 5.0000 1.0000
72.0200 7.0000 1.0000
72.0800 9.0000 1.0000
72.1400 13.0000 1.0000
72.2000 5.0000 1.0000
72.2600 8.0000 1.0000
72.3200 4.0000 1.0000
72.3800 9.0000 1.0000
72.4400 9.0000 1.0000
72.5000 13.0000 1.0000
72.5600 56.0000 1.0000
72.6200 14.0000 1.0000
72.6800 23.0000 1.0000
72.7400 24.0000 1.0000
72.8000 27.0000 1.0000
72.8600 15.0000 1.0000
72.9200 16.0000 1.0000
72.9800 10.0000 1.0000
73.0400 16.0000 1.0000
73.1000 12.0000 1.0000
73.1600 10.0000 1.0000
73.2200 12.0000 1.0000
73.2800 5.0000 1.0000
73.3400 7.0000 1.0000
73.4000 7.0000 1.0000
73.4600 6.0000 1.0000
73.5200 9.0000 1.0000
73.5800 6.0000 1.0000
73.6400 13.0000 1.0000
73.7000 10.0000 1.0000
73.7600 18.0000 1.0000
73.8200 41.0000 1.0000
73.8800 29.0000 1.0000
73.9400 12.0000 1.0000
74.0000 19.0000 1.0000
74.0600 25.0000 1.0000
74.1200 13.0000 1.0000
74.1800 12.0000 1.0000
74.2400 10.0000 1.0000
74.3000 8.0000 1.0000
74.3600 7.0000 1.0000
74.4200 7.0000 1.0000
74.4800 7.0000 1.0000
74.5400 9.0000 1.0000
74.6000 8.0000 1.0000
74.6600 6.0000 1.0000
74.7200 8.0000 1.0000
74.7800 11.0000 1.0000
74.8400 9.0000 1.0000
74.9000 7.0000 1.0000
74.9600 6.0000 1.0000
75.0200 6.0000 1.0000
75.0800 6.0000 1.0000
75.1400 7.0000 1.0000
75.2000 6.0000 1.0000
75.2600 4.0000 1.0000
75.3200 4.0000 1.0000
75.3800 7.0000 1.0000
75.4400 10.0000 1.0000
75.5000 6.0000 1.0000
75.5600 8.0000 1.0000
75.6200 6.0000 1.0000
75.6800 9.0000 1.0000
75.7400 8.0000 1.0000
75.8000 8.0000 1.0000
75.8600 5.0000 1.0000
75.9200 13.0000 1.0000
75.9800 4.0000 1.0000
76.0400 10.0000 1.0000
76.1000 1.0000 1.0000
76.1600 8.0000 1.0000
76.2200 7.0000 1.0000
76.2800 8.0000 1.0000
76.3400 7.0000 1.0000
76.4000 8.0000 1.0000
76.4600 4.0000 1.0000
76.5200 11.0000 1.0000
76.5800 8.0000 1.0000
76.6400 7.0000 1.0000
76.7000 8.0000 1.0000
76.7600 3.0000 1.0000
76.8200 10.0000 1.0000
76.8800 7.0000 1.0000
76.9400 6.0000 1.0000
77.0000 9.0000 1.0000
77.0600 10.0000 1.0000
77.1200 11.0000 1.0000
77.1800 4.0000 1.0000
77.2400 9.0000 1.0000
77.3000 13.0000 1.0000
77.3600 12.0000 1.0000
77.4200 15.0000 1.0000
77.4800 15.0000 1.0000
77.5400 22.0000 1.0000
77.6000 33.0000 1.0000
77.6600 50.0000 1.0000
77.7200 308.0000 1.0000
77.7800 69.0000 1.0000
77.8400 63.0000 1.0000
77.9000 50.0000 1.0000
77.9600 163.0000 1.0000
78.0200 33.0000 1.0000
78.0800 22.0000 1.0000
78.1400 18.0000 1.0000
78.2000 16.0000 1.0000
78.2600 15.0000 1.0000
78.3200 32.0000 1.0000
78.3800 35.0000 1.0000
78.4400 28.0000 1.0000
78.5000 18.0000 1.0000
78.5600 27.0000 1.0000
78.6200 20.0000 1.0000
78.6800 14.0000 1.0000
78.7400 5.0000 1.0000
78.8000 9.0000 1.0000
78.8600 5.0000 1.0000
78.9200 8.0000 1.0000
78.9800 8.0000 1.0000
79.0400 6.0000 1.0000
79.1000 5.0000 1.0000
79.1600 17.0000 1.0000
79.2200 21.0000 1.0000
79.2800 27.0000 1.0000
79.3400 19.0000 1.0000
79.4000 16.0000 1.0000
79.4600 16.0000 1.0000
79.5200 12.0000 1.0000
79.5800 8.0000 1.0000
79.6400 6.0000 1.0000
79.7000 10.0000 1.0000
79.7600 3.0000 1.0000
79.8200 10.0000 1.0000
79.8800 5.0000 1.0000
79.9400 7.0000 1.0000
80.0000 6.0000 1.0000
80.0600 9.0000 1.0000
80.1200 11.0000 1.0000
80.1800 7.0000 1.0000
80.2400 7.0000 1.0000
80.3000 6.0000 1.0000
80.3600 9.0000 1.0000
80.4200 6.0000 1.0000
80.4800 4.0000 1.0000
80.5400 7.0000 1.0000
80.6000 6.0000 1.0000
80.6600 8.0000 1.0000
80.7200 10.0000 1.0000
80.7800 10.0000 1.0000
80.8400 6.0000 1.0000
80.9000 6.0000 1.0000
80.9600 4.0000 1.0000
81.0200 9.0000 1.0000
81.0800 7.0000 1.0000
81.1400 6.0000 1.0000
81.2000 5.0000 1.0000
81.2600 10.0000 1.0000
81.3200 15.0000 1.0000
81.3800 7.0000 1.0000
81.4400 9.0000 1.0000
81.5000 9.0000 1.0000
81.5600 9.0000 1.0000
81.6200 3.0000 1.0000
81.6800 11.0000 1.0000
81.7400 7.0000 1.0000
81.8000 8.0000 1.0000
81.8600 5.0000 1.0000
81.9200 8.0000 1.0000
81.9800 6.0000 1.0000
82.0400 6.0000 1.0000
82.1000 7.0000 1.0000
82.1600 3.0000 1.0000
82.2200 8.0000 1.0000
82.2800 7.0000 1.0000
82.3400 16.0000 1.0000
82.4000 21.0000 1.0000
82.4600 5.0000 1.0000
82.5200 11.0000 1.0000
82.5800 7.0000 1.0000
82.6400 8.0000 1.0000
82.7000 14.0000 1.0000
82.7600 5.0000 1.0000
82.8200 5.0000 1.0000
82.8800 6.0000 1.0000
82.9400 2.0000 1.0000
83.0000 6.0000 1.0000
83.0600 9.0000 1.0000
83.1200 7.0000 1.0000
83.1800 3.0000 1.0000
83.2400 4.0000 1.0000
83.3000 4.0000 1.0000
83.3600 4.0000 1.0000
83.4200 10.0000 1.0000
83.4800 7.0000 1.0000
83.5400 5.0000 1.0000
83.6000 13.0000 1.0000
83.6600 5.0000 1.0000
83.7200 5.0000 1.0000
83.7800 8.0000 1.0000
83.8400 8.0000 1.0000
83.9000 7.0000 1.0000
83.9600 16.0000 1.0000
84.0200 10.0000 1.0000
84.0800 7.0000 1.0000
84.1400 6.0000 1.0000
84.2000 5.0000 1.0000
84.2600 5.0000 1.0000
84.3200 7.0000 1.0000
84.3800 13.0000 1.0000
84.4400 7.0000 1.0000
84.5000 8.0000 1.0000
84.5600 26.0000 1.0000
84.6200 15.0000 1.0000
84.6800 8.0000 1.0000
84.7400 6.0000 1.0000
84.8000 11.0000 1.0000
84.8600 12.0000 1.0000
84.9200 6.0000 1.0000
84.9800 8.0000 1.0000
85.0400 4.0000 1.0000
85.1000 7.0000 1.0000
85.1600 7.0000 1.0000
85.2200 9.0000 1.0000
85.2800 14.0000 1.0000
85.3400 9.0000 1.0000
85.4000 11.0000 1.0000
85.4600 10.0000 1.0000
85.5200 2.0000 1.0000
85.5800 7.0000 1.0000
85.6400 9.0000 1.0000
85.7000 10.0000 1.0000
85.7600 10.0000 1.0000
85.8200 6.0000 1.0000
85.8800 4.0000 1.0000
85.9400 11.0000 1.0000
86.0000 10.0000 1.0000
86.0600 21.0000 1.0000
86.1200 14.0000 1.0000
86.1800 15.0000 1.0000
86.2400 10.0000 1.0000
86.3000 27.0000 1.0000
86.3600 23.0000 1.0000
86.4200 12.0000 1.0000
86.4800 9.0000 1.0000
86.5400 12.0000 1.0000
86.6000 15.0000 1.0000
86.6600 3.0000 1.0000
86.7200 10.0000 1.0000
86.7800 8.0000 1.0000
86.8400 9.0000 1.0000
86.9000 7.0000 1.0000
86.9600 6.0000 1.0000
87.0200 7.0000 1.0000
87.0800 5.0000 1.0000
87.1400 7.0000 1.0000
87.2000 3.0000 1.0000
87.2600 9.0000 1.0000
87.3200 8.0000 1.0000
87.3800 7.0000 1.0000
87.4400 5.0000 1.0000
87.5000 4.0000 1.0000
87.5600 10.0000 1.0000
87.6200 8.0000 1.0000
87.6800 4.0000 1.0000
87.7400 7.0000 1.0000
87.8000 9.0000 1.0000
87.8600 5.0000 1.0000
87.9200 9.0000 1.0000
87.9800 7.0000 1.0000
88.0400 4.0000 1.0000
88.1000 7.0000 1.0000
88.1600 9.0000 1.0000
88.2200 9.0000 1.0000
88.2800 8.0000 1.0000
88.3400 8.0000 1.0000
88.4000 4.0000 1.0000
88.4600 4.0000 1.0000
88.5200 9.0000 1.0000
88.5800 6.0000 1.0000
88.6400 6.0000 1.0000
88.7000 5.0000 1.0000
88.7600 4.0000 1.0000
88.8200 8.0000 1.0000
88.8800 11.0000 1.0000
88.9400 10.0000 1.0000
89.0000 6.0000 1.0000
89.0600 4.0000 1.0000
89.1200 6.0000 1.0000
89.1800 5.0000 1.0000
89.2400 4.0000 1.0000
89.3000 5.0000 1.0000
89.3600 7.0000 1.0000
89.4200 5.0000 1.0000
89.4800 7.0000 1.0000
89.5400 5.0000 1.0000
89.6000 11.0000 1.0000
89.6600 6.0000 1.0000
89.7200 10.0000 1.0000
89.7800 3.0000 1.0000
89.8400 2.0000 1.0000
89.9000 7.0000 1.0000
89.9600 7.0000 1.0000
89.9960 6.0000 1.0000
*RAS_INT_END
*RAS_DATA_END